2021-09-29 12:42:45,906 - sqlalchemy.pool.impl.NullPool - ERROR - Exception during reset or similar
Traceback (most recent call last):
  File "/home/unmsm/remotelab/local/lib/python2.7/site-packages/sqlalchemy/pool/base.py", line 671, in _finalize_fairy
    fairy._reset(pool)
  File "/home/unmsm/remotelab/local/lib/python2.7/site-packages/sqlalchemy/pool/base.py", line 858, in _reset
    pool._dialect.do_rollback(self)
  File "/home/unmsm/remotelab/local/lib/python2.7/site-packages/sqlalchemy/engine/default.py", line 502, in do_rollback
    dbapi_connection.rollback()
ProgrammingError: SQLite objects created in a thread can only be used in that same thread. The object was created in thread id 140139741050624 and this is thread id 140140719789888.
2021-09-29 12:42:45,928 - sqlalchemy.pool.impl.NullPool - ERROR - Exception closing connection <sqlite3.Connection object at 0x7f74edbb0300>
Traceback (most recent call last):
  File "/home/unmsm/remotelab/local/lib/python2.7/site-packages/sqlalchemy/pool/base.py", line 261, in _close_connection
    self._dialect.do_close(connection)
  File "/home/unmsm/remotelab/local/lib/python2.7/site-packages/sqlalchemy/engine/default.py", line 508, in do_close
    dbapi_connection.close()
ProgrammingError: SQLite objects created in a thread can only be used in that same thread. The object was created in thread id 140139741050624 and this is thread id 140140719789888.
2021-10-02 00:23:53,142 - sqlalchemy.pool.impl.NullPool - ERROR - Exception during reset or similar
Traceback (most recent call last):
  File "/home/unmsm/remotelab/local/lib/python2.7/site-packages/sqlalchemy/pool/base.py", line 671, in _finalize_fairy
    fairy._reset(pool)
  File "/home/unmsm/remotelab/local/lib/python2.7/site-packages/sqlalchemy/pool/base.py", line 858, in _reset
    pool._dialect.do_rollback(self)
  File "/home/unmsm/remotelab/local/lib/python2.7/site-packages/sqlalchemy/engine/default.py", line 502, in do_rollback
    dbapi_connection.rollback()
ProgrammingError: SQLite objects created in a thread can only be used in that same thread. The object was created in thread id 139728689026816 and this is thread id 139729485072128.
2021-10-02 00:23:53,143 - sqlalchemy.pool.impl.NullPool - ERROR - Exception closing connection <sqlite3.Connection object at 0x7f151fb894e0>
Traceback (most recent call last):
  File "/home/unmsm/remotelab/local/lib/python2.7/site-packages/sqlalchemy/pool/base.py", line 261, in _close_connection
    self._dialect.do_close(connection)
  File "/home/unmsm/remotelab/local/lib/python2.7/site-packages/sqlalchemy/engine/default.py", line 508, in do_close
    dbapi_connection.close()
ProgrammingError: SQLite objects created in a thread can only be used in that same thread. The object was created in thread id 139728689026816 and this is thread id 139729485072128.
2021-10-02 00:45:55,108 - sqlalchemy.pool.impl.NullPool - ERROR - Exception during reset or similar
Traceback (most recent call last):
  File "/home/unmsm/remotelab/local/lib/python2.7/site-packages/sqlalchemy/pool/base.py", line 671, in _finalize_fairy
    fairy._reset(pool)
  File "/home/unmsm/remotelab/local/lib/python2.7/site-packages/sqlalchemy/pool/base.py", line 858, in _reset
    pool._dialect.do_rollback(self)
  File "/home/unmsm/remotelab/local/lib/python2.7/site-packages/sqlalchemy/engine/default.py", line 502, in do_rollback
    dbapi_connection.rollback()
ProgrammingError: SQLite objects created in a thread can only be used in that same thread. The object was created in thread id 139728689026816 and this is thread id 139729485072128.
2021-10-02 00:45:55,109 - sqlalchemy.pool.impl.NullPool - ERROR - Exception closing connection <sqlite3.Connection object at 0x7f151fcdd210>
Traceback (most recent call last):
  File "/home/unmsm/remotelab/local/lib/python2.7/site-packages/sqlalchemy/pool/base.py", line 261, in _close_connection
    self._dialect.do_close(connection)
  File "/home/unmsm/remotelab/local/lib/python2.7/site-packages/sqlalchemy/engine/default.py", line 508, in do_close
    dbapi_connection.close()
ProgrammingError: SQLite objects created in a thread can only be used in that same thread. The object was created in thread id 139728689026816 and this is thread id 139729485072128.
2021-10-02 00:59:30,746 - sqlalchemy.pool.impl.NullPool - ERROR - Exception during reset or similar
Traceback (most recent call last):
  File "/home/unmsm/remotelab/local/lib/python2.7/site-packages/sqlalchemy/pool/base.py", line 671, in _finalize_fairy
    fairy._reset(pool)
  File "/home/unmsm/remotelab/local/lib/python2.7/site-packages/sqlalchemy/pool/base.py", line 858, in _reset
    pool._dialect.do_rollback(self)
  File "/home/unmsm/remotelab/local/lib/python2.7/site-packages/sqlalchemy/engine/default.py", line 502, in do_rollback
    dbapi_connection.rollback()
ProgrammingError: SQLite objects created in a thread can only be used in that same thread. The object was created in thread id 139728672503552 and this is thread id 139729676502848.
2021-10-02 00:59:30,747 - sqlalchemy.pool.impl.NullPool - ERROR - Exception closing connection <sqlite3.Connection object at 0x7f151fcddc60>
Traceback (most recent call last):
  File "/home/unmsm/remotelab/local/lib/python2.7/site-packages/sqlalchemy/pool/base.py", line 261, in _close_connection
    self._dialect.do_close(connection)
  File "/home/unmsm/remotelab/local/lib/python2.7/site-packages/sqlalchemy/engine/default.py", line 508, in do_close
    dbapi_connection.close()
ProgrammingError: SQLite objects created in a thread can only be used in that same thread. The object was created in thread id 139728672503552 and this is thread id 139729676502848.
2021-10-02 02:06:23,128 - sqlalchemy.pool.impl.NullPool - ERROR - Exception during reset or similar
Traceback (most recent call last):
  File "/home/unmsm/remotelab/local/lib/python2.7/site-packages/sqlalchemy/pool/base.py", line 671, in _finalize_fairy
    fairy._reset(pool)
  File "/home/unmsm/remotelab/local/lib/python2.7/site-packages/sqlalchemy/pool/base.py", line 858, in _reset
    pool._dialect.do_rollback(self)
  File "/home/unmsm/remotelab/local/lib/python2.7/site-packages/sqlalchemy/engine/default.py", line 502, in do_rollback
    dbapi_connection.rollback()
ProgrammingError: SQLite objects created in a thread can only be used in that same thread. The object was created in thread id 139749243221760 and this is thread id 139750104061696.
2021-10-02 02:06:23,130 - sqlalchemy.pool.impl.NullPool - ERROR - Exception closing connection <sqlite3.Connection object at 0x7f19f6f00990>
Traceback (most recent call last):
  File "/home/unmsm/remotelab/local/lib/python2.7/site-packages/sqlalchemy/pool/base.py", line 261, in _close_connection
    self._dialect.do_close(connection)
  File "/home/unmsm/remotelab/local/lib/python2.7/site-packages/sqlalchemy/engine/default.py", line 508, in do_close
    dbapi_connection.close()
ProgrammingError: SQLite objects created in a thread can only be used in that same thread. The object was created in thread id 139749243221760 and this is thread id 139750104061696.
2021-10-02 02:19:35,525 - sqlalchemy.pool.impl.NullPool - ERROR - Exception during reset or similar
Traceback (most recent call last):
  File "/home/unmsm/remotelab/local/lib/python2.7/site-packages/sqlalchemy/pool/base.py", line 671, in _finalize_fairy
    fairy._reset(pool)
  File "/home/unmsm/remotelab/local/lib/python2.7/site-packages/sqlalchemy/pool/base.py", line 858, in _reset
    pool._dialect.do_rollback(self)
  File "/home/unmsm/remotelab/local/lib/python2.7/site-packages/sqlalchemy/engine/default.py", line 502, in do_rollback
    dbapi_connection.rollback()
ProgrammingError: SQLite objects created in a thread can only be used in that same thread. The object was created in thread id 139749243221760 and this is thread id 139750378538816.
2021-10-02 02:19:35,525 - sqlalchemy.pool.impl.NullPool - ERROR - Exception closing connection <sqlite3.Connection object at 0x7f19f71bd300>
Traceback (most recent call last):
  File "/home/unmsm/remotelab/local/lib/python2.7/site-packages/sqlalchemy/pool/base.py", line 261, in _close_connection
    self._dialect.do_close(connection)
  File "/home/unmsm/remotelab/local/lib/python2.7/site-packages/sqlalchemy/engine/default.py", line 508, in do_close
    dbapi_connection.close()
ProgrammingError: SQLite objects created in a thread can only be used in that same thread. The object was created in thread id 139749243221760 and this is thread id 139750378538816.
2021-10-02 02:19:35,525 - sqlalchemy.pool.impl.NullPool - ERROR - Exception during reset or similar
Traceback (most recent call last):
  File "/home/unmsm/remotelab/local/lib/python2.7/site-packages/sqlalchemy/pool/base.py", line 671, in _finalize_fairy
    fairy._reset(pool)
  File "/home/unmsm/remotelab/local/lib/python2.7/site-packages/sqlalchemy/pool/base.py", line 858, in _reset
    pool._dialect.do_rollback(self)
  File "/home/unmsm/remotelab/local/lib/python2.7/site-packages/sqlalchemy/engine/default.py", line 502, in do_rollback
    dbapi_connection.rollback()
ProgrammingError: SQLite objects created in a thread can only be used in that same thread. The object was created in thread id 139749243221760 and this is thread id 139750378538816.
2021-10-02 02:19:35,526 - sqlalchemy.pool.impl.NullPool - ERROR - Exception closing connection <sqlite3.Connection object at 0x7f19f7146d50>
Traceback (most recent call last):
  File "/home/unmsm/remotelab/local/lib/python2.7/site-packages/sqlalchemy/pool/base.py", line 261, in _close_connection
    self._dialect.do_close(connection)
  File "/home/unmsm/remotelab/local/lib/python2.7/site-packages/sqlalchemy/engine/default.py", line 508, in do_close
    dbapi_connection.close()
ProgrammingError: SQLite objects created in a thread can only be used in that same thread. The object was created in thread id 139749243221760 and this is thread id 139750378538816.
