2021-10-02 04:50:35,547 - voodoo.gen.clients - ERROR - u'Error on should_finish'
2021-10-02 04:50:35,547 - voodoo.gen.clients - ERROR - u'Traceback (most recent call last):'
2021-10-02 04:50:35,548 - voodoo.gen.clients - ERROR - u'  File "/home/unmsm/remotelab/local/lib/python2.7/site-packages/voodoo/gen/clients.py", line 59, in _call'
2021-10-02 04:50:35,548 - voodoo.gen.clients - ERROR - u'    return method(*args)'
2021-10-02 04:50:35,548 - voodoo.gen.clients - ERROR - u'  File "/home/unmsm/remotelab/local/lib/python2.7/site-packages/experiments/http_experiment.py", line 270, in do_should_finish'
2021-10-02 04:50:35,548 - voodoo.gen.clients - ERROR - u'    response_str = self._request(url)'
2021-10-02 04:50:35,548 - voodoo.gen.clients - ERROR - u'  File "/home/unmsm/remotelab/local/lib/python2.7/site-packages/experiments/http_experiment.py", line 96, in _request'
2021-10-02 04:50:35,548 - voodoo.gen.clients - ERROR - u'    return urllib2.urlopen(request, context=ctx).read()'
2021-10-02 04:50:35,549 - voodoo.gen.clients - ERROR - u'  File "/usr/lib/python2.7/urllib2.py", line 154, in urlopen'
2021-10-02 04:50:35,549 - voodoo.gen.clients - ERROR - u'    return opener.open(url, data, timeout)'
2021-10-02 04:50:35,549 - voodoo.gen.clients - ERROR - u'  File "/usr/lib/python2.7/urllib2.py", line 429, in open'
2021-10-02 04:50:35,549 - voodoo.gen.clients - ERROR - u'    response = self._open(req, data)'
2021-10-02 04:50:35,549 - voodoo.gen.clients - ERROR - u'  File "/usr/lib/python2.7/urllib2.py", line 447, in _open'
2021-10-02 04:50:35,549 - voodoo.gen.clients - ERROR - u"    '_open', req)"
2021-10-02 04:50:35,549 - voodoo.gen.clients - ERROR - u'  File "/usr/lib/python2.7/urllib2.py", line 407, in _call_chain'
2021-10-02 04:50:35,549 - voodoo.gen.clients - ERROR - u'    result = func(*args)'
2021-10-02 04:50:35,549 - voodoo.gen.clients - ERROR - u'  File "/usr/lib/python2.7/urllib2.py", line 1235, in http_open'
2021-10-02 04:50:35,549 - voodoo.gen.clients - ERROR - u'    return self.do_open(httplib.HTTPConnection, req)'
2021-10-02 04:50:35,549 - voodoo.gen.clients - ERROR - u'  File "/usr/lib/python2.7/urllib2.py", line 1205, in do_open'
2021-10-02 04:50:35,550 - voodoo.gen.clients - ERROR - u'    raise URLError(err)'
2021-10-02 04:50:35,550 - voodoo.gen.clients - ERROR - u'URLError: <urlopen error [Errno 111] Connection refused>'
2021-10-02 04:50:35,550 - voodoo.gen.clients - ERROR - u''
2021-10-02 04:50:35,550 - voodoo.gen.servers - ERROR - u'Error on should_experiment_finish'
2021-10-02 04:50:35,602 - voodoo.gen.servers - ERROR - u'Traceback (most recent call last):'
2021-10-02 04:50:35,602 - voodoo.gen.servers - ERROR - u'  File "/home/unmsm/remotelab/local/lib/python2.7/site-packages/voodoo/gen/servers.py", line 98, in http_method'
2021-10-02 04:50:35,602 - voodoo.gen.servers - ERROR - u'    result = method(*args)'
2021-10-02 04:50:35,602 - voodoo.gen.servers - ERROR - u'  File "/home/unmsm/remotelab/local/lib/python2.7/site-packages/voodoo/log.py", line 386, in wrapped_class_method'
2021-10-02 04:50:35,602 - voodoo.gen.servers - ERROR - u'    result = f(self,*args,**kargs)'
2021-10-02 04:50:35,602 - voodoo.gen.servers - ERROR - u'  File "/home/unmsm/remotelab/local/lib/python2.7/site-packages/voodoo/sessions/checker.py", line 83, in session_checked_wrapper'
2021-10-02 04:50:35,602 - voodoo.gen.servers - ERROR - u'    return_value = func(self, session, *args,**kargs)'
2021-10-02 04:50:35,602 - voodoo.gen.servers - ERROR - u'  File "/home/unmsm/remotelab/local/lib/python2.7/site-packages/weblab/lab/server.py", line 515, in do_should_experiment_finish'
2021-10-02 04:50:35,602 - voodoo.gen.servers - ERROR - u'    return experiment_server.should_finish()'
2021-10-02 04:50:35,603 - voodoo.gen.servers - ERROR - u'  File "/home/unmsm/remotelab/local/lib/python2.7/site-packages/voodoo/gen/clients.py", line 34, in method'
2021-10-02 04:50:35,603 - voodoo.gen.servers - ERROR - u'    return self._call(method_name, *args)'
2021-10-02 04:50:35,603 - voodoo.gen.servers - ERROR - u'  File "/home/unmsm/remotelab/local/lib/python2.7/site-packages/voodoo/gen/clients.py", line 73, in _call'
2021-10-02 04:50:35,603 - voodoo.gen.servers - ERROR - u'    raise InternalCapturedServerCommunicationError(remote_exc_type, remote_exc_args)'
2021-10-02 04:50:35,603 - voodoo.gen.servers - ERROR - u"InternalCapturedServerCommunicationError: InternalCapturedServerCommunicationError(u'urllib2.URLError', (error(111, 'Connection refused'),), (u'urllib2.URLError', (error(111, 'Connection refused'),)))"
2021-10-02 04:50:35,603 - voodoo.gen.servers - ERROR - u''
